[2025-07-02T12:34:25.861+0000] {taskinstance.py:1159} INFO - Dependencies all met for dep_context=non-requeueable deps ti=<TaskInstance: vehiculos_sri_etl_pipeline.extract_load_dim_tiempo scheduled__2025-07-01T00:00:00+00:00 [queued]>
[2025-07-02T12:34:25.887+0000] {taskinstance.py:1159} INFO - Dependencies all met for dep_context=requeueable deps ti=<TaskInstance: vehiculos_sri_etl_pipeline.extract_load_dim_tiempo scheduled__2025-07-01T00:00:00+00:00 [queued]>
[2025-07-02T12:34:25.888+0000] {taskinstance.py:1361} INFO - Starting attempt 2 of 2
[2025-07-02T12:34:25.937+0000] {taskinstance.py:1382} INFO - Executing <Task(PythonOperator): extract_load_dim_tiempo> on 2025-07-01 00:00:00+00:00
[2025-07-02T12:34:25.982+0000] {standard_task_runner.py:57} INFO - Started process 196 to run task
[2025-07-02T12:34:26.026+0000] {standard_task_runner.py:84} INFO - Running: ['***', 'tasks', 'run', 'vehiculos_sri_etl_pipeline', 'extract_load_dim_tiempo', 'scheduled__2025-07-01T00:00:00+00:00', '--job-id', '14', '--raw', '--subdir', 'DAGS_FOLDER/vehiculos_sri_etl.py', '--cfg-path', '/tmp/tmp32xirv_v']
[2025-07-02T12:34:26.044+0000] {standard_task_runner.py:85} INFO - Job 14: Subtask extract_load_dim_tiempo
[2025-07-02T12:34:26.323+0000] {task_command.py:416} INFO - Running <TaskInstance: vehiculos_sri_etl_pipeline.extract_load_dim_tiempo scheduled__2025-07-01T00:00:00+00:00 [running]> on host 1fa40a7dc483
[2025-07-02T12:34:26.607+0000] {taskinstance.py:1662} INFO - Exporting env vars: AIRFLOW_CTX_DAG_OWNER='data-engineer' AIRFLOW_CTX_DAG_ID='vehiculos_sri_etl_pipeline' AIRFLOW_CTX_TASK_ID='extract_load_dim_tiempo' AIRFLOW_CTX_EXECUTION_DATE='2025-07-01T00:00:00+00:00' AIRFLOW_CTX_TRY_NUMBER='2' AIRFLOW_CTX_DAG_RUN_ID='scheduled__2025-07-01T00:00:00+00:00'
[2025-07-02T12:34:26.615+0000] {vehiculos_sri_etl.py:233} INFO - Iniciando procesamiento de DIM_TIEMPO
[2025-07-02T12:34:26.689+0000] {vehiculos_sri_etl.py:50} INFO - Clientes de GCP inicializados correctamente
[2025-07-02T12:34:41.062+0000] {job.py:219} ERROR - Job heartbeat got an exception
Traceback (most recent call last):
  File "/home/airflow/.local/lib/python3.8/site-packages/sqlalchemy/engine/base.py", line 3371, in _wrap_pool_connect
    return fn()
  File "/home/airflow/.local/lib/python3.8/site-packages/sqlalchemy/pool/base.py", line 327, in connect
    return _ConnectionFairy._checkout(self)
  File "/home/airflow/.local/lib/python3.8/site-packages/sqlalchemy/pool/base.py", line 894, in _checkout
    fairy = _ConnectionRecord.checkout(pool)
  File "/home/airflow/.local/lib/python3.8/site-packages/sqlalchemy/pool/base.py", line 493, in checkout
    rec = pool._do_get()
  File "/home/airflow/.local/lib/python3.8/site-packages/sqlalchemy/pool/impl.py", line 256, in _do_get
    return self._create_connection()
  File "/home/airflow/.local/lib/python3.8/site-packages/sqlalchemy/pool/base.py", line 273, in _create_connection
    return _ConnectionRecord(self)
  File "/home/airflow/.local/lib/python3.8/site-packages/sqlalchemy/pool/base.py", line 388, in __init__
    self.__connect()
  File "/home/airflow/.local/lib/python3.8/site-packages/sqlalchemy/pool/base.py", line 691, in __connect
    pool.logger.debug("Error on connect(): %s", e)
  File "/home/airflow/.local/lib/python3.8/site-packages/sqlalchemy/util/langhelpers.py", line 70, in __exit__
    compat.raise_(
  File "/home/airflow/.local/lib/python3.8/site-packages/sqlalchemy/util/compat.py", line 211, in raise_
    raise exception
  File "/home/airflow/.local/lib/python3.8/site-packages/sqlalchemy/pool/base.py", line 686, in __connect
    self.dbapi_connection = connection = pool._invoke_creator(self)
  File "/home/airflow/.local/lib/python3.8/site-packages/sqlalchemy/engine/create.py", line 574, in connect
    return dialect.connect(*cargs, **cparams)
  File "/home/airflow/.local/lib/python3.8/site-packages/sqlalchemy/engine/default.py", line 598, in connect
    return self.dbapi.connect(*cargs, **cparams)
  File "/home/airflow/.local/lib/python3.8/site-packages/psycopg2/__init__.py", line 122, in connect
    conn = _connect(dsn, connection_factory=connection_factory, **kwasync)
psycopg2.OperationalError: could not translate host name "postgres" to address: Temporary failure in name resolution


The above exception was the direct cause of the following exception:

Traceback (most recent call last):
  File "/home/airflow/.local/lib/python3.8/site-packages/airflow/jobs/job.py", line 190, in heartbeat
    session.merge(self)
  File "/home/airflow/.local/lib/python3.8/site-packages/sqlalchemy/orm/session.py", line 3056, in merge
    return self._merge(
  File "/home/airflow/.local/lib/python3.8/site-packages/sqlalchemy/orm/session.py", line 3136, in _merge
    merged = self.get(
  File "/home/airflow/.local/lib/python3.8/site-packages/sqlalchemy/orm/session.py", line 2853, in get
    return self._get_impl(
  File "/home/airflow/.local/lib/python3.8/site-packages/sqlalchemy/orm/session.py", line 2975, in _get_impl
    return db_load_fn(
  File "/home/airflow/.local/lib/python3.8/site-packages/sqlalchemy/orm/loading.py", line 530, in load_on_pk_identity
    session.execute(
  File "/home/airflow/.local/lib/python3.8/site-packages/sqlalchemy/orm/session.py", line 1716, in execute
    conn = self._connection_for_bind(bind)
  File "/home/airflow/.local/lib/python3.8/site-packages/sqlalchemy/orm/session.py", line 1555, in _connection_for_bind
    return self._transaction._connection_for_bind(
  File "/home/airflow/.local/lib/python3.8/site-packages/sqlalchemy/orm/session.py", line 750, in _connection_for_bind
    conn = bind.connect()
  File "/home/airflow/.local/lib/python3.8/site-packages/sqlalchemy/future/engine.py", line 406, in connect
    return super(Engine, self).connect()
  File "/home/airflow/.local/lib/python3.8/site-packages/sqlalchemy/engine/base.py", line 3325, in connect
    return self._connection_cls(self, close_with_result=close_with_result)
  File "/home/airflow/.local/lib/python3.8/site-packages/sqlalchemy/engine/base.py", line 96, in __init__
    else engine.raw_connection()
  File "/home/airflow/.local/lib/python3.8/site-packages/sqlalchemy/engine/base.py", line 3404, in raw_connection
    return self._wrap_pool_connect(self.pool.connect, _connection)
  File "/home/airflow/.local/lib/python3.8/site-packages/sqlalchemy/engine/base.py", line 3374, in _wrap_pool_connect
    Connection._handle_dbapi_exception_noconnection(
  File "/home/airflow/.local/lib/python3.8/site-packages/sqlalchemy/engine/base.py", line 2208, in _handle_dbapi_exception_noconnection
    util.raise_(
  File "/home/airflow/.local/lib/python3.8/site-packages/sqlalchemy/util/compat.py", line 211, in raise_
    raise exception
  File "/home/airflow/.local/lib/python3.8/site-packages/sqlalchemy/engine/base.py", line 3371, in _wrap_pool_connect
    return fn()
  File "/home/airflow/.local/lib/python3.8/site-packages/sqlalchemy/pool/base.py", line 327, in connect
    return _ConnectionFairy._checkout(self)
  File "/home/airflow/.local/lib/python3.8/site-packages/sqlalchemy/pool/base.py", line 894, in _checkout
    fairy = _ConnectionRecord.checkout(pool)
  File "/home/airflow/.local/lib/python3.8/site-packages/sqlalchemy/pool/base.py", line 493, in checkout
    rec = pool._do_get()
  File "/home/airflow/.local/lib/python3.8/site-packages/sqlalchemy/pool/impl.py", line 256, in _do_get
    return self._create_connection()
  File "/home/airflow/.local/lib/python3.8/site-packages/sqlalchemy/pool/base.py", line 273, in _create_connection
    return _ConnectionRecord(self)
  File "/home/airflow/.local/lib/python3.8/site-packages/sqlalchemy/pool/base.py", line 388, in __init__
    self.__connect()
  File "/home/airflow/.local/lib/python3.8/site-packages/sqlalchemy/pool/base.py", line 691, in __connect
    pool.logger.debug("Error on connect(): %s", e)
  File "/home/airflow/.local/lib/python3.8/site-packages/sqlalchemy/util/langhelpers.py", line 70, in __exit__
    compat.raise_(
  File "/home/airflow/.local/lib/python3.8/site-packages/sqlalchemy/util/compat.py", line 211, in raise_
    raise exception
  File "/home/airflow/.local/lib/python3.8/site-packages/sqlalchemy/pool/base.py", line 686, in __connect
    self.dbapi_connection = connection = pool._invoke_creator(self)
  File "/home/airflow/.local/lib/python3.8/site-packages/sqlalchemy/engine/create.py", line 574, in connect
    return dialect.connect(*cargs, **cparams)
  File "/home/airflow/.local/lib/python3.8/site-packages/sqlalchemy/engine/default.py", line 598, in connect
    return self.dbapi.connect(*cargs, **cparams)
  File "/home/airflow/.local/lib/python3.8/site-packages/psycopg2/__init__.py", line 122, in connect
    conn = _connect(dsn, connection_factory=connection_factory, **kwasync)
sqlalchemy.exc.OperationalError: (psycopg2.OperationalError) could not translate host name "postgres" to address: Temporary failure in name resolution

(Background on this error at: https://sqlalche.me/e/14/e3q8)
[2025-07-02T12:34:47.022+0000] {vehiculos_sri_etl.py:68} ERROR - Error leyendo archivo raw-data/matriculaciones_2024.csv: 404 GET https://storage.googleapis.com/download/storage/v1/b/etl-vehiculos-sri/o/raw-data%2Fmatriculaciones_2024.csv?alt=media: The specified bucket does not exist.: ('Request failed with status code', 404, 'Expected one of', <HTTPStatus.OK: 200>, <HTTPStatus.PARTIAL_CONTENT: 206>)
[2025-07-02T12:34:47.023+0000] {taskinstance.py:1937} ERROR - Task failed with exception
Traceback (most recent call last):
  File "/home/airflow/.local/lib/python3.8/site-packages/google/cloud/storage/client.py", line 1099, in download_blob_to_file
    blob_or_uri._do_download(
  File "/home/airflow/.local/lib/python3.8/site-packages/google/cloud/storage/blob.py", line 984, in _do_download
    response = download.consume(transport, timeout=timeout)
  File "/home/airflow/.local/lib/python3.8/site-packages/google/resumable_media/requests/download.py", line 237, in consume
    return _request_helpers.wait_and_retry(
  File "/home/airflow/.local/lib/python3.8/site-packages/google/resumable_media/requests/_request_helpers.py", line 155, in wait_and_retry
    response = func()
  File "/home/airflow/.local/lib/python3.8/site-packages/google/resumable_media/requests/download.py", line 219, in retriable_request
    self._process_response(result)
  File "/home/airflow/.local/lib/python3.8/site-packages/google/resumable_media/_download.py", line 188, in _process_response
    _helpers.require_status_code(
  File "/home/airflow/.local/lib/python3.8/site-packages/google/resumable_media/_helpers.py", line 108, in require_status_code
    raise common.InvalidResponse(
google.resumable_media.common.InvalidResponse: ('Request failed with status code', 404, 'Expected one of', 200, 206)

During handling of the above exception, another exception occurred:

Traceback (most recent call last):
  File "/home/airflow/.local/lib/python3.8/site-packages/airflow/operators/python.py", line 192, in execute
    return_value = self.execute_callable()
  File "/home/airflow/.local/lib/python3.8/site-packages/airflow/operators/python.py", line 209, in execute_callable
    return self.python_callable(*self.op_args, **self.op_kwargs)
  File "/opt/airflow/dags/vehiculos_sri_etl.py", line 238, in extract_and_load_dim_tiempo
    df_main = read_csv_from_gcs(storage_client, BUCKET_NAME, 'raw-data/matriculaciones_2024.csv')
  File "/opt/airflow/dags/vehiculos_sri_etl.py", line 63, in read_csv_from_gcs
    content = blob.download_as_text()
  File "/home/airflow/.local/lib/python3.8/site-packages/google/cloud/storage/blob.py", line 1612, in download_as_text
    data = self.download_as_bytes(
  File "/home/airflow/.local/lib/python3.8/site-packages/google/cloud/storage/blob.py", line 1387, in download_as_bytes
    client.download_blob_to_file(
  File "/home/airflow/.local/lib/python3.8/site-packages/google/cloud/storage/client.py", line 1112, in download_blob_to_file
    _raise_from_invalid_response(exc)
  File "/home/airflow/.local/lib/python3.8/site-packages/google/cloud/storage/blob.py", line 4373, in _raise_from_invalid_response
    raise exceptions.from_http_status(response.status_code, message, response=response)
google.api_core.exceptions.NotFound: 404 GET https://storage.googleapis.com/download/storage/v1/b/etl-vehiculos-sri/o/raw-data%2Fmatriculaciones_2024.csv?alt=media: The specified bucket does not exist.: ('Request failed with status code', 404, 'Expected one of', <HTTPStatus.OK: 200>, <HTTPStatus.PARTIAL_CONTENT: 206>)
[2025-07-02T12:34:47.083+0000] {taskinstance.py:1400} INFO - Marking task as FAILED. dag_id=vehiculos_sri_etl_pipeline, task_id=extract_load_dim_tiempo, execution_date=20250701T000000, start_date=20250702T123425, end_date=20250702T123447
[2025-07-02T12:34:47.229+0000] {standard_task_runner.py:104} ERROR - Failed to execute job 14 for task extract_load_dim_tiempo (404 GET https://storage.googleapis.com/download/storage/v1/b/etl-vehiculos-sri/o/raw-data%2Fmatriculaciones_2024.csv?alt=media: The specified bucket does not exist.: ('Request failed with status code', 404, 'Expected one of', <HTTPStatus.OK: 200>, <HTTPStatus.PARTIAL_CONTENT: 206>); 196)
[2025-07-02T12:34:47.277+0000] {local_task_job_runner.py:228} INFO - Task exited with return code 1
[2025-07-02T12:34:47.341+0000] {taskinstance.py:2778} INFO - 0 downstream tasks scheduled from follow-on schedule check
