[2025-07-02T12:34:29.538+0000] {taskinstance.py:1159} INFO - Dependencies all met for dep_context=non-requeueable deps ti=<TaskInstance: vehiculos_sri_etl_pipeline.extract_load_dim_vehiculo scheduled__2025-07-01T00:00:00+00:00 [queued]>
[2025-07-02T12:34:29.565+0000] {taskinstance.py:1159} INFO - Dependencies all met for dep_context=requeueable deps ti=<TaskInstance: vehiculos_sri_etl_pipeline.extract_load_dim_vehiculo scheduled__2025-07-01T00:00:00+00:00 [queued]>
[2025-07-02T12:34:29.566+0000] {taskinstance.py:1361} INFO - Starting attempt 2 of 2
[2025-07-02T12:34:29.602+0000] {taskinstance.py:1382} INFO - Executing <Task(PythonOperator): extract_load_dim_vehiculo> on 2025-07-01 00:00:00+00:00
[2025-07-02T12:34:29.620+0000] {standard_task_runner.py:57} INFO - Started process 198 to run task
[2025-07-02T12:34:29.632+0000] {standard_task_runner.py:84} INFO - Running: ['***', 'tasks', 'run', 'vehiculos_sri_etl_pipeline', 'extract_load_dim_vehiculo', 'scheduled__2025-07-01T00:00:00+00:00', '--job-id', '16', '--raw', '--subdir', 'DAGS_FOLDER/vehiculos_sri_etl.py', '--cfg-path', '/tmp/tmpuovimln_']
[2025-07-02T12:34:29.638+0000] {standard_task_runner.py:85} INFO - Job 16: Subtask extract_load_dim_vehiculo
[2025-07-02T12:34:29.938+0000] {task_command.py:416} INFO - Running <TaskInstance: vehiculos_sri_etl_pipeline.extract_load_dim_vehiculo scheduled__2025-07-01T00:00:00+00:00 [running]> on host 1fa40a7dc483
[2025-07-02T12:34:39.977+0000] {standard_task_runner.py:104} ERROR - Failed to execute job 16 for task extract_load_dim_vehiculo ((psycopg2.OperationalError) could not translate host name "postgres" to address: Temporary failure in name resolution

(Background on this error at: https://sqlalche.me/e/14/e3q8); 198)
[2025-07-02T12:34:44.682+0000] {job.py:219} ERROR - Job heartbeat got an exception
Traceback (most recent call last):
  File "/home/airflow/.local/lib/python3.8/site-packages/sqlalchemy/engine/base.py", line 3371, in _wrap_pool_connect
    return fn()
  File "/home/airflow/.local/lib/python3.8/site-packages/sqlalchemy/pool/base.py", line 327, in connect
    return _ConnectionFairy._checkout(self)
  File "/home/airflow/.local/lib/python3.8/site-packages/sqlalchemy/pool/base.py", line 894, in _checkout
    fairy = _ConnectionRecord.checkout(pool)
  File "/home/airflow/.local/lib/python3.8/site-packages/sqlalchemy/pool/base.py", line 493, in checkout
    rec = pool._do_get()
  File "/home/airflow/.local/lib/python3.8/site-packages/sqlalchemy/pool/impl.py", line 256, in _do_get
    return self._create_connection()
  File "/home/airflow/.local/lib/python3.8/site-packages/sqlalchemy/pool/base.py", line 273, in _create_connection
    return _ConnectionRecord(self)
  File "/home/airflow/.local/lib/python3.8/site-packages/sqlalchemy/pool/base.py", line 388, in __init__
    self.__connect()
  File "/home/airflow/.local/lib/python3.8/site-packages/sqlalchemy/pool/base.py", line 691, in __connect
    pool.logger.debug("Error on connect(): %s", e)
  File "/home/airflow/.local/lib/python3.8/site-packages/sqlalchemy/util/langhelpers.py", line 70, in __exit__
    compat.raise_(
  File "/home/airflow/.local/lib/python3.8/site-packages/sqlalchemy/util/compat.py", line 211, in raise_
    raise exception
  File "/home/airflow/.local/lib/python3.8/site-packages/sqlalchemy/pool/base.py", line 686, in __connect
    self.dbapi_connection = connection = pool._invoke_creator(self)
  File "/home/airflow/.local/lib/python3.8/site-packages/sqlalchemy/engine/create.py", line 574, in connect
    return dialect.connect(*cargs, **cparams)
  File "/home/airflow/.local/lib/python3.8/site-packages/sqlalchemy/engine/default.py", line 598, in connect
    return self.dbapi.connect(*cargs, **cparams)
  File "/home/airflow/.local/lib/python3.8/site-packages/psycopg2/__init__.py", line 122, in connect
    conn = _connect(dsn, connection_factory=connection_factory, **kwasync)
psycopg2.OperationalError: could not translate host name "postgres" to address: Temporary failure in name resolution


The above exception was the direct cause of the following exception:

Traceback (most recent call last):
  File "/home/airflow/.local/lib/python3.8/site-packages/airflow/jobs/job.py", line 190, in heartbeat
    session.merge(self)
  File "/home/airflow/.local/lib/python3.8/site-packages/sqlalchemy/orm/session.py", line 3056, in merge
    return self._merge(
  File "/home/airflow/.local/lib/python3.8/site-packages/sqlalchemy/orm/session.py", line 3136, in _merge
    merged = self.get(
  File "/home/airflow/.local/lib/python3.8/site-packages/sqlalchemy/orm/session.py", line 2853, in get
    return self._get_impl(
  File "/home/airflow/.local/lib/python3.8/site-packages/sqlalchemy/orm/session.py", line 2975, in _get_impl
    return db_load_fn(
  File "/home/airflow/.local/lib/python3.8/site-packages/sqlalchemy/orm/loading.py", line 530, in load_on_pk_identity
    session.execute(
  File "/home/airflow/.local/lib/python3.8/site-packages/sqlalchemy/orm/session.py", line 1716, in execute
    conn = self._connection_for_bind(bind)
  File "/home/airflow/.local/lib/python3.8/site-packages/sqlalchemy/orm/session.py", line 1555, in _connection_for_bind
    return self._transaction._connection_for_bind(
  File "/home/airflow/.local/lib/python3.8/site-packages/sqlalchemy/orm/session.py", line 750, in _connection_for_bind
    conn = bind.connect()
  File "/home/airflow/.local/lib/python3.8/site-packages/sqlalchemy/future/engine.py", line 406, in connect
    return super(Engine, self).connect()
  File "/home/airflow/.local/lib/python3.8/site-packages/sqlalchemy/engine/base.py", line 3325, in connect
    return self._connection_cls(self, close_with_result=close_with_result)
  File "/home/airflow/.local/lib/python3.8/site-packages/sqlalchemy/engine/base.py", line 96, in __init__
    else engine.raw_connection()
  File "/home/airflow/.local/lib/python3.8/site-packages/sqlalchemy/engine/base.py", line 3404, in raw_connection
    return self._wrap_pool_connect(self.pool.connect, _connection)
  File "/home/airflow/.local/lib/python3.8/site-packages/sqlalchemy/engine/base.py", line 3374, in _wrap_pool_connect
    Connection._handle_dbapi_exception_noconnection(
  File "/home/airflow/.local/lib/python3.8/site-packages/sqlalchemy/engine/base.py", line 2208, in _handle_dbapi_exception_noconnection
    util.raise_(
  File "/home/airflow/.local/lib/python3.8/site-packages/sqlalchemy/util/compat.py", line 211, in raise_
    raise exception
  File "/home/airflow/.local/lib/python3.8/site-packages/sqlalchemy/engine/base.py", line 3371, in _wrap_pool_connect
    return fn()
  File "/home/airflow/.local/lib/python3.8/site-packages/sqlalchemy/pool/base.py", line 327, in connect
    return _ConnectionFairy._checkout(self)
  File "/home/airflow/.local/lib/python3.8/site-packages/sqlalchemy/pool/base.py", line 894, in _checkout
    fairy = _ConnectionRecord.checkout(pool)
  File "/home/airflow/.local/lib/python3.8/site-packages/sqlalchemy/pool/base.py", line 493, in checkout
    rec = pool._do_get()
  File "/home/airflow/.local/lib/python3.8/site-packages/sqlalchemy/pool/impl.py", line 256, in _do_get
    return self._create_connection()
  File "/home/airflow/.local/lib/python3.8/site-packages/sqlalchemy/pool/base.py", line 273, in _create_connection
    return _ConnectionRecord(self)
  File "/home/airflow/.local/lib/python3.8/site-packages/sqlalchemy/pool/base.py", line 388, in __init__
    self.__connect()
  File "/home/airflow/.local/lib/python3.8/site-packages/sqlalchemy/pool/base.py", line 691, in __connect
    pool.logger.debug("Error on connect(): %s", e)
  File "/home/airflow/.local/lib/python3.8/site-packages/sqlalchemy/util/langhelpers.py", line 70, in __exit__
    compat.raise_(
  File "/home/airflow/.local/lib/python3.8/site-packages/sqlalchemy/util/compat.py", line 211, in raise_
    raise exception
  File "/home/airflow/.local/lib/python3.8/site-packages/sqlalchemy/pool/base.py", line 686, in __connect
    self.dbapi_connection = connection = pool._invoke_creator(self)
  File "/home/airflow/.local/lib/python3.8/site-packages/sqlalchemy/engine/create.py", line 574, in connect
    return dialect.connect(*cargs, **cparams)
  File "/home/airflow/.local/lib/python3.8/site-packages/sqlalchemy/engine/default.py", line 598, in connect
    return self.dbapi.connect(*cargs, **cparams)
  File "/home/airflow/.local/lib/python3.8/site-packages/psycopg2/__init__.py", line 122, in connect
    conn = _connect(dsn, connection_factory=connection_factory, **kwasync)
sqlalchemy.exc.OperationalError: (psycopg2.OperationalError) could not translate host name "postgres" to address: Temporary failure in name resolution

(Background on this error at: https://sqlalche.me/e/14/e3q8)
[2025-07-02T12:34:44.713+0000] {local_task_job_runner.py:228} INFO - Task exited with return code 1
[2025-07-02T12:34:47.122+0000] {taskinstance.py:2778} INFO - 0 downstream tasks scheduled from follow-on schedule check
